<?xml version="1.0" encoding="utf-8"?>
<robot>
  <link name="world"/>
  <link name="inertia1_centroidal">
    <inertial>
      <origin xyz="0.091 0.0 0.0" rpy="0.0 0.0 0.0"/>
      <mass value="23.902"/>
      <inertia ixx="0.0" ixy="0.0" ixz="0.0" iyy="1.266" iyz="0.0" izz="0.0"/>
    </inertial>
  </link>
  <link name="inertia2_centroidal">
    <inertial>
      <origin xyz="0.048 0.0 0.0" rpy="0.0 0.0 0.0"/>
      <mass value="1.285"/>
      <inertia ixx="0.0" ixy="0.0" ixz="0.0" iyy="0.093" iyz="0.0" izz="0.0"/>
    </inertial>
  </link>
  <joint name="joint1" type="continuous">
    <parent link="world"/>
    <child link="inertia1_centroidal"/>
    <origin xyz="0.0 0.0 0.0" rpy="0.0 -0.0 0.0"/>
    <axis xyz="0.0 -1.0 0.0"/>
    <limit effort="Inf" velocity="Inf"/>
  </joint>
  <joint name="joint2" type="continuous">
    <parent link="inertia1_centroidal"/>
    <child link="inertia2_centroidal"/>
    <origin xyz="0.45 0.0 0.0" rpy="0.0 -0.0 0.0"/>
    <axis xyz="0.0 -1.0 0.0"/>
    <limit effort="Inf" velocity="Inf"/>
  </joint>
</robot>
